<?xml version="1.0" ?>
<robot name="mouse" xmlns:xacro="http://www.ros.org/wiki/xacro">
  <material name="black">
    <color rgba="0.0 0.0 0.0 1.0"/>
  </material>
  <material name="blue">
    <color rgba="0.203125 0.23828125 0.28515625 1.0"/>
  </material>
  <material name="green">
    <color rgba="0.0 0.8 0.0 1.0"/>
  </material>
  <material name="grey">
    <color rgba="0.2 0.2 0.2 1.0"/>
  </material>
  <material name="orange">
    <color rgba="1.0 0.423529411765 0.0392156862745 1.0"/>
  </material>
  <material name="brown">
    <color rgba="0.870588235294 0.811764705882 0.764705882353 1.0"/>
  </material>
  <material name="red">
    <color rgba="0.80078125 0.12890625 0.1328125 1.0"/>
  </material>
  <material name="white">
    <color rgba="1.0 1.0 1.0 1.0"/>
  </material>
  
  <gazebo reference="link_chassis">
    <material>Gazebo/Orange</material>
  </gazebo>
  <gazebo reference="link_caster">
    <material>Gazebo/Gray</material>
  </gazebo>
  <gazebo reference="link_left_wheel">
    <material>Gazebo/Blue</material>
  </gazebo>
  <gazebo reference="link_right_wheel">
    <material>Gazebo/Blue</material>
  </gazebo>
  
  <!-- =========================================== -->
  <!-- ============ ROBOT DESCRIPTION ============ -->
  <!-- =========================================== -->
  <!-- Chassis -->
  <link name="link_chassis">
    <collision name="collision_chassis">
    <origin rpy="0 0 0" xyz="0.05 0 0.05"/> <!-- 0.00 0 0.038-->
      <geometry>
        <box size="0.5 0.32 0.09"/>
      </geometry>
    </collision>
    <visual>
      <origin rpy="0 0 0" xyz="0 0 0"/>
      <geometry>
        <mesh filename="package://micromouse/meshes/collision/umouse2_align.stl" scale="3.5 3.5 3.5"/>
      </geometry>
      <material name="blue"/>
    </visual>
  </link>

  <joint name="fixed_base_joint" type="fixed">
    <origin rpy="0 0 0" xyz="0 0 0"/>
    <child link="chassis_inertia"/>
    <parent link="link_chassis"/>
  </joint>

  <link name="chassis_inertia">
    <inertial>
      <mass value="5"/>
      <origin rpy="0 0 0" xyz="0.05 0 0.05"/><!-- 0.11 0 0.0028-->
      <inertia ixx="0.0460416" ixy="0" ixz="0" iyy="0.10754166" iyz="0" izz="0.1468333"/>
    </inertial>
  </link>

  <!-- Front castor wheel -->
  <joint name="fixed_caster_joint" type="continuous">
    <origin rpy="0 0 0" xyz="0.28 0 -0.015"/>
    <child link="link_caster"/>
    <parent link="link_chassis"/>
  </joint>

  <link name="link_caster">
    <collision name="caster_front_collision">
      <origin rpy="0 0 0" xyz="0 0 -0.015"/>
      <geometry>
        <sphere radius="0.023"/>
      </geometry>
      <surface>
        <friction>
          <ode>
            <mu>0</mu>
            <mu2>0</mu2>
            <slip1>1.0</slip1>
            <slip2>1.0</slip2>
          </ode>
        </friction>
      </surface>
    </collision>
    <inertial>
      <origin rpy="0 0 0" xyz="0 0 -0.015"/>
      <mass value="0.1" />
      <inertia ixx="0.000014516" ixy="0.0" ixz="0.0" iyy="0.000014516" iyz="0.0" izz="0.000014516"/>
    </inertial>
    <visual name="caster_front_visual">
      <origin rpy="0 0 0" xyz="0 0 -0.015"/>
      <geometry>
        <sphere radius="0.023"/>
      </geometry>
    </visual>
  </link>

  <!-- Back castor wheel -->
  <joint name="fixed_bcaster_joint" type="continuous">
    <origin rpy="0 0 0" xyz="-0.11 0 -0.015"/>
    <child link="link_bcaster"/>
    <parent link="link_chassis"/>
  </joint>

  <link name="link_bcaster">
    <collision name="caster_back_collision">
      <origin rpy="0 0 0" xyz="0 0 -0.015"/>
      <geometry>
        <sphere radius="0.023"/>
      </geometry>
      <surface>
        <friction>
          <ode>
            <mu>0</mu>
            <mu2>0</mu2>
            <slip1>1.0</slip1>
            <slip2>1.0</slip2>
          </ode>
        </friction>
      </surface>
    </collision>
    <inertial>
      <origin rpy="0 0 0" xyz="0 0 -0.015"/>
      <mass value="0.1" />
      <inertia ixx="0.000014516" ixy="0.0" ixz="0.0" iyy="0.000014516" iyz="0.0" izz="0.000014516"/>
    </inertial>
    <visual name="caster_back_visual">
      <origin rpy="0 0 0" xyz="0 0 -0.015"/>
      <geometry>
        <sphere radius="0.023"/>
      </geometry>
    </visual>
  </link>

<!-- Left wheel -->
  <link name="link_left_wheel">
    <inertial>
      <mass value="0.2"/>
      <origin rpy="0 1.5707 -1.5707" xyz="0 0 0"/>
      <inertia ixx="0.000252" ixy="0" ixz="0" iyy="0.000252" iyz="0" izz="0.000486"/>
    </inertial>
    <collision name="link_left_wheel_collision">
      <origin rpy="0 1.570796 1.570796" xyz="0 0 0"/>
      <geometry>
        <cylinder length="0.022" radius="0.066"/>
      </geometry>
    </collision>
    <visual name="link_left_wheel_visual">
      <origin rpy="0 0 0" xyz="0 0 0"/>
      <geometry>
        <mesh filename="package://micromouse/meshes/collision/wheel_r2.stl" scale="3.5 3.5 3.5"/>
      </geometry>
    </visual>
  </link>
  
  <joint name="joint_left_wheel" type="continuous">
    <origin rpy="0 0 0" xyz="0 0.178 0.028"/>
    <child link="link_left_wheel"/>
    <parent link="link_chassis"/>
    <axis rpy="0 0 0" xyz="0 1 0"/>
    <limit effort="10000" velocity="1000"/>
    <joint_properties damping="1.0" friction="1.0"/>
  </joint>
  
<!-- Right wheel -->  
  <link name="link_right_wheel">
    <inertial>
      <mass value="0.2"/>
      <origin rpy="0 1.5707 -1.5707" xyz="0 0 0"/>
      <inertia ixx="0.000252" ixy="0" ixz="0" iyy="0.000252" iyz="0" izz="0.000486"/>
    </inertial>
    <collision name="link_right_wheel_collision">
      <origin rpy="0 1.570796 1.570796" xyz="0 0 0"/>
      <geometry>
        <cylinder length="0.022" radius="0.066"/>
      </geometry>
    </collision>
    <visual name="link_right_wheel_visual">
      <origin rpy="0 0 0" xyz="0 0 0"/>
      <geometry>
        <mesh filename="package://micromouse/meshes/collision/wheel_l2.stl" scale="3.5 3.5 3.5"/>
      </geometry>
    </visual>
  </link>
  
  <joint name="joint_right_wheel" type="continuous">
    <origin rpy="0 0 0" xyz="0 -0.178 0.028"/>
    <child link="link_right_wheel"/>
    <parent link="link_chassis"/>
    <axis rpy="0 0 0" xyz="0 1 0"/>
    <limit effort="10000" velocity="1000"/>
    <joint_properties damping="1.0" friction="1.0"/>
  </joint>

<!-- IMU Sensor -->
  <link name="imu_link"/>

  <joint name="imu_joint" type="fixed">
    <parent link="link_chassis"/>
    <child link="imu_link"/>
    <origin xyz="0 0 0" rpy="0 0 0"/>
  </joint>

  <gazebo reference="imu_link">
    <sensor type="imu" name="imu">
      <always_on>true</always_on>
      <visualize>true</visualize>
    </sensor>
    <material>Gazebo/Grey</material>
  </gazebo>

  <gazebo>
    <plugin name="imu_plugin" filename="libgazebo_ros_imu.so">
      <alwaysOn>true</alwaysOn>
      <bodyName>imu_link</bodyName>
      <frameName>imu_link</frameName>
      <topicName>imu</topicName>
      <serviceName>imu_service</serviceName>
      <gaussianNoise>0.0</gaussianNoise>
      <updateRate>200</updateRate>
      <imu>
        <noise>
          <type>gaussian</type>
          <rate>
            <mean>0.0</mean>
            <stddev>2e-4</stddev>
            <bias_mean>0.0000075</bias_mean>
            <bias_stddev>0.0000008</bias_stddev>
          </rate>
          <accel>
            <mean>0.0</mean>
            <stddev>1.7e-2</stddev>
            <bias_mean>0.1</bias_mean>
            <bias_stddev>0.001</bias_stddev>
          </accel>
        </noise>
      </imu>
    </plugin>
  </gazebo>

  <!-- LiDAR Sensor -->
  <joint name="scan_joint" type="fixed">
    <parent link="link_chassis"/>
    <child link="link_scan"/>
    <origin xyz="0.185 0 0.155" rpy="0 0 -1.57079"/>
  </joint>

  <link name="link_scan">
    <visual>
      <origin xyz="0 0 0" rpy="0 0 0"/>
      <geometry>
        <box size="0.00001 0.00001 0.00001"/>
      </geometry>
      <material name="black"/>
    </visual>
    <collision>
      <origin xyz="0 0 0" rpy="0 0 0"/>
      <geometry>
        <box size="0.00001 0.00001 0.00001"/>
      </geometry>
    </collision>
  </link>

  <gazebo reference="link_scan">
    <sensor type="ray" name="lidar_sensor">
      <pose>0 0 0 0 0 0</pose>
      <visualize>true</visualize>
      <update_rate>5</update_rate>
      <ray>
        <scan>
          <horizontal>
            <samples>360</samples>
            <resolution>1</resolution>
            <min_angle>0.0</min_angle>
            <max_angle>3.14159</max_angle>
          </horizontal>
        </scan>
        <range>
          <min>0.12</min>
          <max>4.8</max>
          <resolution>0.015</resolution>
        </range>
        <noise>
          <type>gaussian</type>
          <mean>0.0</mean>
          <stddev>0.01</stddev>
        </noise>
      </ray>
      <plugin name="gazebo_ros_lidar_controller" filename="libgazebo_ros_laser.so">
        <topicName>scan</topicName>
        <frameName>link_scan</frameName>
      </plugin>
    </sensor>
    <material>Gazebo/FlatBlack</material>
  </gazebo>

  <!-- Controller -->
  <gazebo>
    <plugin name="mouse_controller" filename="libgazebo_ros_diff_drive.so">
      <commandTopic>cmd_vel</commandTopic>
      <odometryTopic>odom</odometryTopic>
      <odometryFrame>odom</odometryFrame>
      <odometrySource>world</odometrySource>
      <publishOdomTF>true</publishOdomTF>
      <robotBaseFrame>link_chassis</robotBaseFrame>
      <publishWheelTF>false</publishWheelTF>
      <publishTf>true</publishTf>
      <publishWheelJointState>true</publishWheelJointState>
      <legacyMode>false</legacyMode>
      <updateRate>30</updateRate>
      <leftJoint>joint_left_wheel</leftJoint>
      <rightJoint>joint_right_wheel</rightJoint>
      <wheelSeparation>0.03</wheelSeparation>
      <wheelDiameter>0.02</wheelDiameter>
      <wheelAcceleration>1</wheelAcceleration>
      <wheelTorque>10</wheelTorque>
      <rosDebugLevel>na</rosDebugLevel>
    </plugin>
  </gazebo>
</robot>