<?xml version="1.0" ?>
<robot name="microgiit2" xmlns:xacro="http://www.ros.org/wiki/xacro">

<!-- Include macros.xacro -->
  <xacro:include filename="$(find micromouse)/urdf/materiales.xacro" />
  <xacro:include filename="$(find micromouse)/urdf/micromouse2.gazebo" />
  <xacro:include filename="$(find micromouse)/urdf/macros.xacro" />

<!-- Chasiss -->
<link name="link_chassis">
    <!-- pose and inertial -->
    <pose>0 0 0 0 0 0</pose>
    <inertial>
      <mass value="5"/>
      <origin rpy="0 0 0" xyz="0.0 0 0"/>
      <inertia ixx="0.0395416666667" ixy="0" ixz="0" iyy="0.106208333333" iyz="0" izz="0.14166666667"/>
    </inertial>
    <!-- body -->
    <collision name="collision_chassis">
    <origin rpy="0 0 0" xyz="0 0 0"/>
      <geometry>
        <mesh filename="package://micromouse/meshes/collision/chasis.stl" scale="1 1 1"/>
      </geometry>
    </collision>
    <visual>
      <origin rpy="0 0 0" xyz="0 0 0"/>
      <geometry>
        <mesh filename="package://micromouse/meshes/collision/chasis.stl" scale="1 1 1"/>
      </geometry>
      <material name="blue"/>
    </visual>
</link>

<!-- caster front -->
<link name="caster_front_ball">
    <inertial>
      <mass value="0.1"/>
      <origin rpy="0 0 0" xyz="0 0 0"/>
      <inertia ixx="0.000526666666667" ixy="0" ixz="0" iyy="0.000526666666667" iyz="0" izz="0.000526666666667"/>
    </inertial>
    <collision name="caster_front_collision">
      <origin rpy=" 0 0 0" xyz="0 0 0"/>
      <geometry>
        <sphere radius="0.005"/>
      </geometry>
      <surface>
        <friction>
          <ode>
            <mu>0</mu>
            <mu2>0</mu2>
            <slip1>1.0</slip1>
            <slip2>1.0</slip2>
          </ode>
        </friction>
      </surface>
    </collision>
    <visual name="caster_front_visual">
      <origin rpy=" 0 0 0" xyz="0 0 0"/>
      <geometry>
        <sphere radius="0.005"/>
      </geometry>
    </visual>
</link>

<joint name="joint_casterfront_chasis" type="continuous">
  <origin rpy="0 0 0" xyz="0.1 0 -0.011"/>
  <child link="caster_front_ball"/>
  <parent link="link_chassis"/>
</joint>

<!-- caster back}
<link name="caster_back_ball">
    <inertial>
      <mass value="0.1"/>
      <origin rpy="0 0 0" xyz="0 0 0"/>
      <inertia ixx="0.000526666666667" ixy="0" ixz="0" iyy="0.000526666666667" iyz="0" izz="0.000526666666667"/>
    </inertial>
    <collision name="caster_back_collision">
      <origin rpy=" 0 0 0" xyz="0 0 0"/>
      <geometry>
        <sphere radius="0.0052"/>
      </geometry>
      <surface>
        <friction>
          <ode>
            <mu>0</mu>
            <mu2>0</mu2>
            <slip1>1.0</slip1>
            <slip2>1.0</slip2>
          </ode>
        </friction>
      </surface>
    </collision>
    <visual name="caster_back_visual">
      <origin rpy=" 0 0 0" xyz="0 0 0"/>
      <geometry>
        <sphere radius="0.0052"/>
      </geometry>
    </visual>
</link>

<joint name="joint_casterback_chasis" type="continuous">
  <origin rpy="0 0 0" xyz="-0.036 0 -0.011"/>
  <child link="caster_back_ball"/>
  <parent link="link_chassis"/>
</joint> -->
<!-- 
   IR sensor    
  <joint name="ir_front_joint" type="fixed">
      <axis xyz="0 1 0" />
      <origin rpy="0 0 0" xyz="0.07 0 -0.09" />
      <parent link="link_chassis"/>
      <child link="base_ir_front"/>
  </joint>
  <link name="base_ir_front">
      <collision>
        <origin xyz="0 0 0" rpy="0 0 0"/>
        <geometry>
          <box size="0.001 0.001 0.001"/>
        </geometry>
      </collision>
      <visual>
        <origin xyz="0 0 0" rpy="0 0 0"/>
        <geometry>
          <box size="0.001 0.001 0.001"/>
        </geometry>
      </visual>
      <inertial>
        <mass value="1e-5" />
        <origin xyz="0 0 0" rpy="0 0 0"/>
        <inertia ixx="1e-6" ixy="0" ixz="0" iyy="1e-6" iyz="0"      izz="1e-6" />
      </inertial>
  </link> -->
  
<!-- Macros -->

<!-- right wheel-->
  <xacro:link_wheel name="link_right_wheel" />
  <xacro:joint_wheel name="joint_right_wheel" child="link_right_wheel" origin_xyz="0 -0.058 0" origin_rpy="0 0 0"/>

<!-- left wheel-->
  <xacro:link_wheel name="link_left_wheel" />
  <xacro:joint_wheel name="joint_left_wheel" child="link_left_wheel" origin_xyz="0 0.058 0" origin_rpy="0 0 3.1416"/>
  
</robot>