<?xml version="1.0" ?>
<!-- =================================================================================== -->
<!-- |    This document was autogenerated by xacro from robotfr.xacro                  | -->
<!-- |    EDITING THIS FILE BY HAND IS NOT RECOMMENDED                                 | -->
<!-- =================================================================================== -->
<!-- Archivo xacro del robot -->
<robot name="robotfr" xmlns:xacro="http://ros.org/wiki/xacro">
  <material name="black">
    <color rgba="0.0 0.0 0.0 1.0"/>
  </material>
  <material name="blue">
    <color rgba="0.203125 0.23828125 0.28515625 1.0"/>
  </material>
  <material name="green">
    <color rgba="0.0 0.8 0.0 1.0"/>
  </material>
  <material name="grey">
    <color rgba="0.2 0.2 0.2 1.0"/>
  </material>
  <material name="orange">
    <color rgba="1.0 0.423529411765 0.0392156862745 1.0"/>
  </material>
  <material name="brown">
    <color rgba="0.870588235294 0.811764705882 0.764705882353 1.0"/>
  </material>
  <material name="red">
    <color rgba="0.80078125 0.12890625 0.1328125 1.0"/>
  </material>
  <material name="white">
    <color rgba="1.0 1.0 1.0 1.0"/>
  </material>
  <material name="c_link1">
    <color rgba="0.83 0.83 0.83 1"/>
  </material>
  <material name="c_link2">
    <color rgba="1 0.65 0 1"/>
  </material>
  <material name="c_link3">
    <color rgba="0.83 0.83 0.83 1"/>
  </material>
  <material name="c_link4">
    <color rgba="1 0.65 0 1"/>
  </material>
  <material name="c_link5">
    <color rgba="0.44 0.5 0.56 1"/>
  </material>
  <material name="c_link6">
    <color rgba="0.83 0.83 0.83 1"/>
  </material>
  <material name="c_base_link">
    <color rgba="0.44 0.5 0.56 1"/>
  </material>
  <gazebo reference="base_link">
    <material>Gazebo/Black</material>
  </gazebo>
  <gazebo reference="Link1">
    <material>Gazebo/DarkGrey</material>
  </gazebo>
  <gazebo reference="Link2">
    <material>Gazebo/RedBright</material>
  </gazebo>
  <gazebo reference="Link3">
    <material>Gazebo/DarkGrey</material>
  </gazebo>
  <gazebo reference="Link4">
    <material>Gazebo/RedBright</material>
  </gazebo>
  <gazebo reference="Link5">
    <material>Gazebo/DarkGrey</material>
  </gazebo>
  <gazebo reference="Link6">
    <material>Gazebo/RedBright</material>
  </gazebo>
  <!-- Base del robot ('base_link')-->
  <link name="base_link">
    <!-- Propiedades inerciales-->
    <inertial>
      <origin rpy="0 0 0" xyz="0.00072554 2.2065E-05 0.024268"/>
      <mass value="0.01"/>
      <inertia ixx="10" ixy="0" ixz="0" iyy="10" iyz="0" izz="10"/>
    </inertial>
    <!-- Visualizacion del robot-->
    <visual>
      <origin rpy="0 0 0" xyz="0 0 0"/>
      <geometry>
        <!-- Enmallado -->
        <mesh filename="package://projectfr/meshes/base_link.STL"/>
      </geometry>
      <material name="c_base_link"/>
    </visual>
    <!-- Propiedades de colision -->
    <collision>
      <origin rpy="0 0 0" xyz="0 0 0"/>
      <geometry>
        <!-- Enmallado -->
        <mesh filename="package://projectfr/meshes/base_link.STL"/>
      </geometry>
    </collision>
  </link>
  <!-- Link 1 ('Link1')-->
  <link name="Link1">
    <!-- Propiedades inerciales -->
    <inertial>
      <origin rpy="0 0 0" xyz="0.011601 0.022341 0.044136"/>
      <mass value="0.001"/>
      <inertia ixx="10" ixy="0" ixz="0" iyy="10" iyz="0" izz="10"/>
    </inertial>
    <!-- Propiedades de visualizacion -->
    <visual>
      <origin rpy="0 0 0" xyz="0 0 0"/>
      <geometry>
        <!-- Enmallado -->
        <mesh filename="package://projectfr/meshes/Link1.STL"/>
      </geometry>
      <material name="white"/>
    </visual>
    <!-- Propiedades de colision -->
    <collision>
      <origin rpy="0 0 0" xyz="0 0 0"/>
      <geometry>
        <mesh filename="package://projectfr/meshes/Link1.STL"/>
      </geometry>
    </collision>
    <!-- Articulacion entre Base_Link y Link1 ('joint1')-->
  </link>
  <joint name="joint1" type="revolute">
    <!-- Tipo revolucion -->
    <!-- Propiedades de la articulacion-->
    <origin rpy="0 0 0" xyz="0 0 0.065406"/>
    <parent link="base_link"/>
    <child link="Link1"/>
    <axis xyz="0 0 1"/>
    <limit effort="200" lower="-1.7453" upper="2.7925" velocity="200"/>
  </joint>
  <!-- Link 2 ('Link2')-->
  <link name="Link2">
    <!-- Propiedades inerciales -->
    <inertial>
      <origin rpy="0 0 0" xyz="0.054694 0.0036383 -0.0056108"/>
      <mass value="0.001"/>
      <inertia ixx="10" ixy="0" ixz="0" iyy="10" iyz="0" izz="10"/>
    </inertial>
    <!-- Propiedades de visualizacion-->
    <visual>
      <origin rpy="0 0 0" xyz="0 0 0"/>
      <geometry>
        <!-- Enmallado -->
        <mesh filename="package://projectfr/meshes/Link2.STL"/>
      </geometry>
      <material name="red"/>
    </visual>
    <!-- Propiedades de colision-->
    <collision>
      <origin rpy="0 0 0" xyz="0 0 0"/>
      <geometry>
        <!-- Enmallado -->
        <mesh filename="package://projectfr/meshes/Link2.STL"/>
      </geometry>
    </collision>
  </link>
  <!-- Articulacion entre Link1 y Link2 ('joint2')-->
  <joint name="joint2" type="revolute">
    <!-- Tipo revolucion-->
    <!-- Propiedades de la articulacion-->
    <origin rpy="3.1402 -1.5708 1.5722" xyz="0.029687 -0.022 0.061593"/>
    <parent link="Link1"/>
    <child link="Link2"/>
    <axis xyz="0 0 1"/>
    <limit effort="200" lower="-0.5235" upper="1.2217" velocity="200"/>
  </joint>
  <!-- Link 3 ('Link3')-->
  <link name="Link3">
    <!-- Propiedades inerciales -->
    <inertial>
      <origin rpy="0 0 0" xyz="0.0099997 0.0071403 0.037517"/>
      <mass value="0.001"/>
      <inertia ixx="10" ixy="0" ixz="0" iyy="10" iyz="0" izz="10"/>
    </inertial>
    <!-- Propiedades de visualizacion-->
    <visual>
      <origin rpy="0 0 0" xyz="0 0 0"/>
      <geometry>
        <!-- Enmallado -->
        <mesh filename="package://projectfr/meshes/Link3.STL"/>
      </geometry>
      <material name="white"/>
    </visual>
    <!-- Propiedades de colision-->
    <collision>
      <origin rpy="0 0 0" xyz="0 0 0"/>
      <geometry>
        <!-- Enmallado -->
        <mesh filename="package://projectfr/meshes/Link3.STL"/>
      </geometry>
    </collision>
  </link>
  <!-- Articulacion entre el Link2 y el Link3 ('joint3')-->
  <joint name="joint3" type="revolute">
    <!-- Tipo revolucion-->
    <!-- Propiedades de la articulacion-->
    <origin rpy="0 0 0" xyz="0.108 0 -0.0094471"/>
    <parent link="Link2"/>
    <child link="Link3"/>
    <axis xyz="0 0 1"/>
    <limit effort="200" lower="-2.9671" upper="1.0472" velocity="200"/>
  </joint>
  <!-- Link 4 ('Link4')-->
  <link name="Link4">
    <!-- Propiedades inerciales -->
    <inertial>
      <origin rpy="0 0 0" xyz="-8.0804E-06 0.0043797 0.040569"/>
      <mass value="0.001"/>
      <inertia ixx="10" ixy="0" ixz="0" iyy="10" iyz="0" izz="10"/>
    </inertial>
    <!-- Propiedades de visualizacion-->
    <visual>
      <origin rpy="0 0 0" xyz="0 0 0"/>
      <geometry>
        <!-- Enmallado -->
        <mesh filename="package://projectfr/meshes/Link4.STL"/>
      </geometry>
      <material name="red"/>
    </visual>
    <!-- Propiedades de colision-->
    <collision>
      <origin rpy="0 0 0" xyz="0 0 0"/>
      <geometry>
        <!-- Enmallado -->
        <mesh filename="package://projectfr/meshes/Link4.STL"/>
      </geometry>
    </collision>
    <!-- Articulacion entre link3 y link4 ('joint4')-->
  </link>
  <joint name="joint4" type="revolute">
    <!-- Tipo revolucion-->
    <!-- Propiedades de la articulacion-->
    <origin rpy="-1.5708 0 0" xyz="0.020001 0.10743 0.031439"/>
    <parent link="Link3"/>
    <child link="Link4"/>
    <axis xyz="0 0 1"/>
    <limit effort="200" lower="-6.1086" upper="6.1086" velocity="200"/>
  </joint>
  <!-- Link 5 ('Link5')-->
  <link name="Link5">
    <!-- Propiedades inerciales -->
    <inertial>
      <origin rpy="0 0 0" xyz="0.00025302 -0.0020133 0.010352"/>
      <mass value="0.001"/>
      <inertia ixx="10" ixy="0" ixz="0" iyy="10" iyz="0" izz="10"/>
    </inertial>
    <!-- Propiedades de visualizacion-->
    <visual>
      <origin rpy="0 0 0" xyz="0 0 0"/>
      <geometry>
        <!-- Enmallado -->
        <mesh filename="package://projectfr/meshes/Link5.STL"/>
      </geometry>
      <material name="white"/>
    </visual>
    <!-- Propiedades de colision-->
    <collision>
      <origin rpy="0 0 0" xyz="0 0 0"/>
      <geometry>
        <!-- Enmallado -->
        <mesh filename="package://projectfr/meshes/Link5.STL"/>
      </geometry>
    </collision>
    <!-- Articulacion entre Link4 y Link5 ('Joint5')-->
  </link>
  <joint name="joint5" type="revolute">
    <!-- Tipo revolucion-->
    <origin rpy="1.5708 -1.5708 -3.1416" xyz="0 -0.010414 0.06155"/>
    <parent link="Link4"/>
    <child link="Link5"/>
    <axis xyz="0 0 -1"/>
    <limit effort="200" lower="-3.5779" upper="0.6283" velocity="200"/>
  </joint>
  <!-- Link 6 ('Link6')-->
  <link name="Link6">
    <!-- Propiedades inerciales-->
    <inertial>
      <origin rpy="0 0 0" xyz="5.5511E-17 5.421E-20 -0.010506"/>
      <mass value="0.001"/>
      <inertia ixx="10" ixy="0" ixz="0" iyy="10" iyz="0" izz="10"/>
    </inertial>
    <!-- Propiedades de visualizacion-->
    <visual>
      <origin rpy="0 0 0" xyz="0 0 0"/>
      <geometry>
        <!-- Enmallado-->
        <mesh filename="package://projectfr/meshes/Link6.STL"/>
      </geometry>
      <material name="white"/>
    </visual>
    <!-- Propiedades de colision -->
    <collision>
      <origin rpy="0 0 0" xyz="0 0 0"/>
      <geometry>
        <!-- Enmallado-->
        <mesh filename="package://projectfr/meshes/Link6.STL"/>
      </geometry>
    </collision>
  </link>
  <!-- Articulacion entre el Link 5 y Link 6 ('joint6')-->
  <joint name="joint6" type="revolute">
    <!-- Tipo revolucion-->
    <!-- Propiedades de la articulacion-->
    <origin rpy="-1.5708 0 0" xyz="0 -0.01628 0.010525"/>
    <parent link="Link5"/>
    <child link="Link6"/>
    <axis xyz="0 0 1"/>
    <limit effort="200" lower="-6.2832" upper="6.2832" velocity="200"/>
  </joint>
  <!-- Transmissions for ROS Control 
  <xacro:macro name="transmission_block" params="joint_name">
    <transmission name="tran1">
      <type>transmission_interface/SimpleTransmission</type>
      <joint name="${joint_name}">
        <hardwareInterface>hardware_interface/PositionJointInterface</hardwareInterface>
      </joint>
      <actuator name="motor1">
        <hardwareInterface>hardware_interface/PositionJointInterface</hardwareInterface>
        <mechanicalReduction>1</mechanicalReduction>
      </actuator>
    </transmission>
  </xacro:macro> -->
  <transmission name="tran1">
    <type>transmission_interface/SimpleTransmission</type>
    <joint name="joint1">
      <hardwareInterface>hardware_interface/EffortJointInterface</hardwareInterface>
    </joint>
    <actuator name="motor1">
      <hardwareInterface>hardware_interface/EffortJointInterface</hardwareInterface>
      <mechanicalReduction>1</mechanicalReduction>
    </actuator>
  </transmission>
  <transmission name="tran2">
    <type>transmission_interface/SimpleTransmission</type>
    <joint name="joint2">
      <hardwareInterface>hardware_interface/EffortJointInterface</hardwareInterface>
    </joint>
    <actuator name="motor2">
      <hardwareInterface>hardware_interface/EffortJointInterface</hardwareInterface>
      <mechanicalReduction>1</mechanicalReduction>
    </actuator>
  </transmission>
  <transmission name="tran3">
    <type>transmission_interface/SimpleTransmission</type>
    <joint name="joint3">
      <hardwareInterface>hardware_interface/EffortJointInterface</hardwareInterface>
    </joint>
    <actuator name="motor3">
      <hardwareInterface>hardware_interface/EffortJointInterface</hardwareInterface>
      <mechanicalReduction>1</mechanicalReduction>
    </actuator>
  </transmission>
  <transmission name="tran4">
    <type>transmission_interface/SimpleTransmission</type>
    <joint name="joint4">
      <hardwareInterface>hardware_interface/EffortJointInterface</hardwareInterface>
    </joint>
    <actuator name="motor4">
      <hardwareInterface>hardware_interface/EffortJointInterface</hardwareInterface>
      <mechanicalReduction>1</mechanicalReduction>
    </actuator>
  </transmission>
  <transmission name="tran5">
    <type>transmission_interface/SimpleTransmission</type>
    <joint name="joint5">
      <hardwareInterface>hardware_interface/EffortJointInterface</hardwareInterface>
    </joint>
    <actuator name="motor5">
      <hardwareInterface>hardware_interface/EffortJointInterface</hardwareInterface>
      <mechanicalReduction>1</mechanicalReduction>
    </actuator>
  </transmission>
  <transmission name="tran6">
    <type>transmission_interface/SimpleTransmission</type>
    <joint name="joint6">
      <hardwareInterface>hardware_interface/EffortJointInterface</hardwareInterface>
    </joint>
    <actuator name="motor6">
      <hardwareInterface>hardware_interface/EffortJointInterface</hardwareInterface>
      <mechanicalReduction>1</mechanicalReduction>
    </actuator>
  </transmission>
  <!-- ros_control plugin -->
  <gazebo>
    <plugin filename="libgazebo_ros_control.so" name="gazebo_ros_control">
      <robotNamespace>/robotfr</robotNamespace>
      <robotSimType>gazebo_ros_control/DefaultRobotHWSim</robotSimType>
      <legacyModeNS>true</legacyModeNS>
    </plugin>
  </gazebo>
</robot>

